<?xml version="1.0" ?>
<robot name="xArm">


  <material name="dark">
    <color rgba="0.3 0.3 0.3 1.0"/>
  </material>
  <material name="black">
    <color rgba="0.1 0.1 0.1 1.0"/>
  </material>
  <material name="light_black">
    <color rgba="0.4 0.4 0.4 1.0"/>
  </material>
  <material name="lightblue">
    <color rgba="0.0 0.0 0.8 1.0"/>
  </material>
  <material name="green">
    <color rgba="0.0 0.8 0.0 1.0"/>
  </material>
  <material name="white">
    <color rgba="0.9 0.9 0.9 1.0"/>
  </material>
  <material name="blue">
	<color rgba="0.3 0.5 0.9 1.0"/>
  </material>

  <joint name="base_joint" type="fixed">
    <parent link="base_footprint"/>
    <child link="base_link"/>
    <origin xyz="0.0 0.0 0.125" rpy="0 0 0"/>
  </joint>

  <joint name="scan_joint" type="fixed">
    <parent link="base_link"/>
    <child link="base_scan"/>
    <origin xyz="0.1 -0.065 0.08" rpy="0 0 3.1415"/>
  </joint>

  <joint name="imu_joint" type="fixed">
    <parent link="base_link"/>
    <child link="imu_link"/>
    <origin xyz="0.15 0 0.025" rpy="0 0 0"/>
  </joint>

  <joint name="wheel_left_joint" type="fixed">
    <parent link="base_link"/>
    <child link="wheel_left_link"/>
    <origin xyz="0 0.215 -0.065" rpy="0 0 0"/>
    <axis xyz="0 0 1"/>
  </joint>

  <joint name="wheel_right_joint" type="fixed">
    <parent link="base_link"/>
    <child link="wheel_right_link"/>
    <origin xyz="0 -0.215 -0.065" rpy="0 0 0"/>
    <axis xyz="0 0 1"/>
  </joint>


  <link name="base_footprint"/>

  <link name="base_link">
    <visual>
      <origin rpy="0 0 0" xyz="0 0 0.0"/>
      <geometry>
        <box size="0.405 0.28 0.115"/>
      </geometry>
      <material name="white"/>
    </visual>
  </link>

  <link name="imu_link">
    <visual>
      <origin rpy="0 0 0" xyz="-0.03 0 0.0"/>
      <geometry>
        <box size="0.18 0.18 0.002"/>
      </geometry>
      <material name="lightblue"/>
    </visual>
  </link>

  <link name="base_scan">
    <visual>
      <origin xyz="0 0 0.0" rpy="0 0 0"/>
      <geometry>
        <cylinder length="0.0315" radius="0.035"/>
      </geometry>
      <material name="dark"/>
    </visual>

    <collision>
      <origin xyz="0.015 0 -0.0065" rpy="0 0 0"/>
      <geometry>
        <cylinder length="0.0315" radius="0.055"/>
      </geometry>
    </collision>

  </link>

  <link name="wheel_left_link">
    <visual>
      <origin xyz="0 0 0" rpy="1.57 0 0"/>
      <geometry>
        <cylinder length="0.065" radius="0.06"/>
      </geometry>
      <material name="dark"/>
    </visual>
    <visual>
      <origin xyz="0.225 0 0" rpy="1.57 0 0"/>
      <geometry>
        <cylinder length="0.065" radius="0.06"/>
      </geometry>
      <material name="dark"/>
    </visual>
    <visual>
      <origin xyz="-0.225 0 0" rpy="1.57 0 0"/>
      <geometry>
        <cylinder length="0.065" radius="0.06"/>
      </geometry>
      <material name="dark"/>
    </visual>         
  </link>  

  <link name="wheel_right_link">
    <visual>
      <origin xyz="0 0 0" rpy="1.57 0 0"/>
      <geometry>
        <cylinder length="0.065" radius="0.06"/>
      </geometry>
      <material name="dark"/>
    </visual>
    <visual>
      <origin xyz="0.225 0 0" rpy="1.57 0 0"/>
      <geometry>
        <cylinder length="0.065" radius="0.06"/>
      </geometry>
      <material name="dark"/>
    </visual>
    <visual>
      <origin xyz="-0.225 0 0" rpy="1.57 0 0"/>
      <geometry>
        <cylinder length="0.065" radius="0.06"/>
      </geometry>
      <material name="dark"/>
    </visual>         
  </link>  

<!--arm_to_brover_link-->

  <link name="arm_to_brover_link">
    <visual>
      <origin rpy="0 0 0" xyz="-0.005 0.0 0.055"/>
      <geometry>
        <box size="0.1 0.1 0.005"/>
      </geometry>
      <material name="blue"/>
    </visual>
  </link>


  <joint name="arm_to_brover_joint" type="fixed">
    <parent link="base_link"/>
    <child link="arm_to_brover_link"/>
    <origin rpy="0 1.57 0" xyz="0.15 -0.05 -0.015"/>
  </joint>


<!--arm_joint_1-->

  <joint name="arm1" type="revolute">
    <parent link="arm_to_brover_link"/>
    <child link="link1"/>
    <origin rpy="0.0 0.0 0.0" xyz="0.0 0.0 0.06"/>
    <axis xyz="0 0 1"/>
    <limit effort="100" velocity="1.0" lower="-3.42" upper="0.7" />
  </joint>

<!--arm_link_1-->

  <link name="link1">
    <visual>
      <origin rpy="0 0 0.0" xyz="0 0 0.0065"/>
      <geometry>
        <cylinder length="0.013" radius="0.04"/>
      </geometry>
      <material name="blue"/>
    </visual>
    <visual>
      <origin rpy="0 0 0" xyz="0.011 0.0 0.01625"/>
      <geometry>
        <box size="0.044 0.0285 0.0065"/>
      </geometry>
      <material name="blue"/>
    </visual>
    <visual>
      <origin rpy="0 0 0" xyz="0.011 0.0 0.031"/>
      <geometry>
        <box size="0.044 0.0285 0.023"/>
      </geometry>
      <material name="black"/>
    </visual>
  </link>

<!--arm_joint_2-->

  <joint name="arm2" type="revolute">
    <parent link="link1"/>
    <child link="link2"/>
    <origin rpy="0.0 0.0 0.0" xyz="0.0 0.0 0.0425"/>
    <axis xyz="0 1 0"/>
    <limit effort="100" velocity="1.0" lower="-1.51" upper="1.51" />
  </joint>

<!--arm_link_2-->

  <link name="link2">
    <visual>
      <origin rpy="0 0 0" xyz="0.0 0.02 0.0135"/>
      <geometry>
        <box size="0.032 0.002 0.052"/>
      </geometry>
      <material name="blue"/>
    </visual>
    <visual>
      <origin rpy="0 0 0" xyz="0.0 -0.02 0.0135"/>
      <geometry>
        <box size="0.032 0.002 0.052"/>
      </geometry>
      <material name="blue"/>
    </visual>
    <visual>
      <origin rpy="0 0 0" xyz="0.0 0.0 0.0385"/>
      <geometry>
        <box size="0.032 0.042 0.002"/>
      </geometry>
      <material name="blue"/>
    </visual>
    <visual>
      <origin rpy="0 0 1.57075" xyz="0 0 0.054"/>
      <geometry>
        <cylinder length="0.029" radius="0.012"/>
      </geometry>
      <material name="black"/>
    </visual>
    <visual>
      <origin rpy="0 0 0" xyz="0.0 0.0 0.0695"/>
      <geometry>
        <box size="0.025 0.042 0.002"/>
      </geometry>
      <material name="blue"/>
    </visual>
    <visual>
      <origin rpy="0 0 0" xyz="0.0 0.02 0.091"/>
      <geometry>
        <box size="0.025 0.002 0.045"/>
      </geometry>
      <material name="blue"/>
    </visual>
    <visual>
      <origin rpy="0 0 0" xyz="0.0 -0.02 0.091"/>
      <geometry>
        <box size="0.025 0.002 0.045"/>
      </geometry>
      <material name="blue"/>
    </visual>
  </link>

<!--arm_joint_3-->

  <joint name="arm3" type="revolute">
    <parent link="link2"/>
    <child link="link3"/>
    <origin rpy="0.0 0.0 0.0" xyz="0.0 0.0 0.0965"/>
    <axis xyz="0 1 0"/>
    <limit effort="100" velocity="1.0" lower="-2.12" upper="2.01" />
  </joint>

<!--arm_link_3-->

  <link name="link3">
    <visual>
      <origin rpy="0 0 0" xyz="0.0 0.0 0.011"/>
      <geometry>
        <box size="0.023 0.0285 0.044"/>
      </geometry>
      <material name="black"/>
    </visual>
    <visual>
      <origin rpy="0 0 0" xyz="0.0 0.0 0.035"/>
      <geometry>
        <box size="0.023 0.0285 0.004"/>
      </geometry>
      <material name="blue"/>
    </visual>
    <visual>
      <origin rpy="0 0 1.57075" xyz="0 0 0.0475"/>
      <geometry>
        <cylinder length="0.021" radius="0.0105"/>
      </geometry>
      <material name="black"/>
    </visual>
    <visual>
      <origin rpy="0 0 0" xyz="0.0 0.0 0.060"/>
      <geometry>
        <box size="0.023 0.0285 0.004"/>
      </geometry>
      <material name="blue"/>
    </visual>
    <visual>
      <origin rpy="0 0 0" xyz="0.0 0.0 0.084"/>
      <geometry>
        <box size="0.023 0.0285 0.044"/>
      </geometry>
      <material name="black"/>
    </visual>
  </link>


<!--arm_joint_4-->

  <joint name="arm4" type="revolute">
    <parent link="link3"/>
    <child link="link4"/>
    <origin rpy="0.0 0.0 0.0" xyz="0.0 0.0 0.0965"/>
    <axis xyz="0 1 0"/>
    <limit effort="100" velocity="1.0" lower="-1.92" upper="2.15" />
  </joint>

<!--arm_link_4-->

  <link name="link4">
    <visual>
      <origin rpy="0 0 0" xyz="0.0 0.02 0.0195"/>
      <geometry>
        <box size="0.025 0.002 0.064"/>
      </geometry>
      <material name="blue"/>
    </visual>
    <visual>
      <origin rpy="0 0 0" xyz="0.0 -0.02 0.0195"/>
      <geometry>
        <box size="0.025 0.002 0.064"/>
      </geometry>
      <material name="blue"/>
    </visual>
    <visual>
      <origin rpy="0 0 0" xyz="0.0 0.0 0.0505"/>
      <geometry>
        <box size="0.025 0.042 0.002"/>
      </geometry>
      <material name="blue"/>
    </visual>
    <visual>
      <origin rpy="0 0 0" xyz="-0.011 0.0 0.03525"/>
      <geometry>
        <box size="0.044 0.023 0.0285"/>
      </geometry>
      <material name="black"/>
    </visual>
  </link>

<!--arm_joint_5-->

  <joint name="arm5" type="revolute">
    <parent link="link4"/>
    <child link="link5"/>
    <origin rpy="0.0 0.0 0.0" xyz="0.0 0.0 0.055"/>
    <axis xyz="0 0 1"/>
    <limit effort="100" velocity="1.0" lower="-0.46" upper="3.73" />
  </joint>

<!--arm_link_5-->

  <link name="link5">
    <visual>
      <origin rpy="0 0 0.0" xyz="0 0 0"/>
      <geometry>
        <cylinder length="0.004" radius="0.01"/>
      </geometry>
      <material name="black"/>
    </visual>
  </link>

<!--gripper_link-->
  <link name="gripper_link">
    <visual>
      <geometry>
        <box size="0.01 0.06 0.004"/>
      </geometry>
      <origin rpy="0 0 0" xyz="0 0 0.002"/>
      <material name="black"/>
    </visual>
    <collision>
      <geometry>
        <box size="0.01 0.06 0.004"/>
      </geometry>
      <origin rpy="0 0 0" xyz="0 0 0.002"/>
    </collision>
    <visual>
      <origin rpy="0 0 0" xyz="-0.025 0.0 -0.02"/>
      <geometry>
        <box size="0.04 0.039 0.023"/>
      </geometry>
      <material name="black"/>
    </visual>
        <visual>
      <origin rpy="0 0 0" xyz="0.0 0.0 -0.03"/>
      <geometry>
        <box size="0.01 0.012 0.06"/>
      </geometry>
      <material name="black"/>
    </visual>
  </link>
  <joint name="gripper_to_arm" type="fixed">
    <origin rpy="0 0 0" xyz="0 0 0.05"/>
    <parent link="link5"/>
    <child link="gripper_link"/>
  </joint>
  
  <!--left_gripper_finger-->
  <link name="left_gripper">
    <visual>
      <geometry>
        <box size="0.01 0.01 0.032"/>
      </geometry>
      <origin rpy="0 0 0" xyz="0 0 0.016"/>
      <material name="black"/>
    </visual>
    <collision>
      <geometry>
        <box size="0.01 0.01 0.032"/>
      </geometry>
      <origin rpy="0 0 0" xyz="0 0 0.016"/>
    </collision>
  </link>
  <joint name="gripper1" type="prismatic">
    <origin rpy="0 0 0" xyz="0 -0.01 0.004"/>
    <parent link="gripper_link"/>
    <child link="left_gripper"/>
    <axis xyz="0 1 0"/>
    <limit effort="16" lower="0" upper="0.03" velocity="2"/>
    <dynamics damping="50" friction="1"/>
  </joint>
  
  <!--right_gripper_finger-->
  <link name="right_gripper">
    <visual>
      <geometry>
        <box size="0.01 0.01 0.032"/>
      </geometry>
      <origin rpy="0 0 0" xyz="0 0 0.016"/>
      <material name="black"/>
    </visual>
    <collision>
      <geometry>
        <box size="0.01 0.01 0.032"/>
      </geometry>
      <origin rpy="0 0 0" xyz="0 0 0.016"/>
    </collision>
  </link>
  <joint name="gripper2" type="prismatic">
    <origin rpy="0 0 0" xyz="0 0.01 0.004"/>
    <parent link="gripper_link"/>
    <child link="right_gripper"/>
    <axis xyz="0 1 0"/>
    <limit effort="16" lower="-0.03" upper="0" velocity="2"/>
    <mimic joint="gripper1" multiplier="-1"/>
    <dynamics damping="50" friction="1"/>
  </joint>
</robot>
